Workbook

Sheet Sheet1
A1: Thời điểm | B1: Ngày - giờ | C1: thời gian (giờ) | D1: ngày | E1: tháng | F1: lat | G1: lon | H1: trạng thái | I1: cường độ (cấp BF) | J1: Vmax (km/h) | K1: tốc độ di chuyển (km/h) | L1: hướng di chuyển | M1: Pmin (mb) | N1: bán kính gió mạnh cấp 6 (km) | O1: bán kính gió mạnh cấp 10 (km) | P1: bán kính tâm (km)
A2: quá khứ | B2: =TEXT(D2,"00")&"/"&TEXT(E2,"00")&" - "&C2&"h" -> 04/11 - 01h | C2: 01 | D2: 4 | E2: 11 | F2: 8.1 | G2: 147.8 | H2: =INDEX(Thang_BF!$A$2:$A$223, MATCH(I2, Thang_BF!$B$2:$B$223, 0)) -> vungthap | I2: =INDEX(Thang_BF!$B$2:$B$223, MATCH(J2, Thang_BF!$C$2:$C$223, 0)) -> 05 | J2: 30 | K2: =(G2-G3)*111/3 -> 11.1 | L2: tây tây bắc | M2: 1004
A3: quá khứ | B3: =TEXT(D3,"00")&"/"&TEXT(E3,"00")&" - "&C3&"h" -> 04/11 - 04h | C3: 04 | D3: 4 | E3: 11 | F3: 8.1 | G3: 147.5 | H3: =INDEX(Thang_BF!$A$2:$A$223, MATCH(I3, Thang_BF!$B$2:$B$223, 0)) -> vungthap | I3: =INDEX(Thang_BF!$B$2:$B$223, MATCH(J3, Thang_BF!$C$2:$C$223, 0)) -> 05 | J3: 30 | K3: =(G3-G4)*111/3 -> 40.7 | L3: tây tây bắc | M3: 1004
A4: quá khứ | B4: =TEXT(D4,"00")&"/"&TEXT(E4,"00")&" - "&C4&"h" -> 04/11 - 07h | C4: 07 | D4: 4 | E4: 11 | F4: 8.2 | G4: 146.4 | H4: =INDEX(Thang_BF!$A$2:$A$223, MATCH(I4, Thang_BF!$B$2:$B$223, 0)) -> vungthap | I4: =INDEX(Thang_BF!$B$2:$B$223, MATCH(J4, Thang_BF!$C$2:$C$223, 0)) -> 05 | J4: 30 | K4: =(G4-G5)*111/3 -> 66.6 | L4: tây tây bắc | M4: 1004
A5: quá khứ | B5: =TEXT(D5,"00")&"/"&TEXT(E5,"00")&" - "&C5&"h" -> 04/11 - 10h | C5: 10 | D5: 4 | E5: 11 | F5: 8.5 | G5: 144.6 | H5: =INDEX(Thang_BF!$A$2:$A$223, MATCH(I5, Thang_BF!$B$2:$B$223, 0)) -> vungthap | I5: =INDEX(Thang_BF!$B$2:$B$223, MATCH(J5, Thang_BF!$C$2:$C$223, 0)) -> 05 | J5: 30 | K5: =(G5-G6)*111/3 -> 3.7 | L5: tây tây bắc | M5: 1004
A6: quá khứ | B6: =TEXT(D6,"00")&"/"&TEXT(E6,"00")&" - "&C6&"h" -> 04/11 - 13h | C6: 13 | D6: 4 | E6: 11 | F6: 8.6 | G6: 144.5 | H6: =INDEX(Thang_BF!$A$2:$A$223, MATCH(I6, Thang_BF!$B$2:$B$223, 0)) -> vungthap | I6: =INDEX(Thang_BF!$B$2:$B$223, MATCH(J6, Thang_BF!$C$2:$C$223, 0)) -> 05 | J6: 30 | K6: =(G6-G7)*111/3 -> 11.1 | L6: tây tây bắc | M6: 1004
A7: quá khứ | B7: =TEXT(D7,"00")&"/"&TEXT(E7,"00")&" - "&C7&"h" -> 04/11 - 16h | C7: 16 | D7: 4 | E7: 11 | F7: 8.6 | G7: 144.2 | H7: =INDEX(Thang_BF!$A$2:$A$223, MATCH(I7, Thang_BF!$B$2:$B$223, 0)) -> vungthap | I7: =INDEX(Thang_BF!$B$2:$B$223, MATCH(J7, Thang_BF!$C$2:$C$223, 0)) -> 05 | J7: 30 | K7: =(G7-G8)*111/3 -> 3.7 | L7: tây tây bắc | M7: 1004
A8: quá khứ | B8: =TEXT(D8,"00")&"/"&TEXT(E8,"00")&" - "&C8&"h" -> 04/11 - 19h | C8: 19 | D8: 4 | E8: 11 | F8: 8.2 | G8: 144.1 | H8: =INDEX(Thang_BF!$A$2:$A$223, MATCH(I8, Thang_BF!$B$2:$B$223, 0)) -> TD | I8: =INDEX(Thang_BF!$B$2:$B$223, MATCH(J8, Thang_BF!$C$2:$C$223, 0)) -> 06 | J8: 39 | K8: =(G8-G9)*111/3 -> 3.7 | L8: tây tây bắc | M8: 1002
A9: quá khứ | B9: =TEXT(D9,"00")&"/"&TEXT(E9,"00")&" - "&C9&"h" -> 04/11 - 22h | C9: 22 | D9: 4 | E9: 11 | F9: 8.5 | G9: 144 | H9: =INDEX(Thang_BF!$A$2:$A$223, MATCH(I9, Thang_BF!$B$2:$B$223, 0)) -> TD | I9: =INDEX(Thang_BF!$B$2:$B$223, MATCH(J9, Thang_BF!$C$2:$C$223, 0)) -> 06 | J9: 39 | K9: =(G9-G10)*111/3 -> 7.4 | L9: tây tây bắc | M9: 1002
A10: quá khứ | B10: =TEXT(D10,"00")&"/"&TEXT(E10,"00")&" - "&C10&"h" -> 05/11 - 01h | C10: 01 | D10: 5 | E10: 11 | F10: 8.3 | G10: 143.8 | H10: =INDEX(Thang_BF!$A$2:$A$223, MATCH(I10, Thang_BF!$B$2:$B$223, 0)) -> TD | I10: =INDEX(Thang_BF!$B$2:$B$223, MATCH(J10, Thang_BF!$C$2:$C$223, 0)) -> 06 | J10: 45 | K10: =(G10-G11)*111/3 -> 11.1 | L10: tây tây bắc | M10: 1002
A11: quá khứ | B11: =TEXT(D11,"00")&"/"&TEXT(E11,"00")&" - "&C11&"h" -> 05/11 - 04h | C11: 04 | D11: 5 | E11: 11 | F11: 8.4 | G11: 143.5 | H11: =INDEX(Thang_BF!$A$2:$A$223, MATCH(I11, Thang_BF!$B$2:$B$223, 0)) -> TD | I11: =INDEX(Thang_BF!$B$2:$B$223, MATCH(J11, Thang_BF!$C$2:$C$223, 0)) -> 07 | J11: 50 | K11: =(G11-G12)*111/3 -> 18.5 | L11: tây tây bắc | M11: 1002
A12: quá khứ | B12: =TEXT(D12,"00")&"/"&TEXT(E12,"00")&" - "&C12&"h" -> 05/11 - 07h | C12: 07 | D12: 5 | E12: 11 | F12: 7.8 | G12: 143 | H12: =INDEX(Thang_BF!$A$2:$A$223, MATCH(I12, Thang_BF!$B$2:$B$223, 0)) -> TD | I12: =INDEX(Thang_BF!$B$2:$B$223, MATCH(J12, Thang_BF!$C$2:$C$223, 0)) -> 07 | J12: 50 | K12: =(G12-G13)*111/3 -> 3.7 | L12: tây tây bắc | M12: 1002
A13: quá khứ | B13: =TEXT(D13,"00")&"/"&TEXT(E13,"00")&" - "&C13&"h" -> 05/11 - 10h | C13: 10 | D13: 5 | E13: 11 | F13: 8 | G13: 142.9 | H13: =INDEX(Thang_BF!$A$2:$A$223, MATCH(I13, Thang_BF!$B$2:$B$223, 0)) -> TD | I13: =INDEX(Thang_BF!$B$2:$B$223, MATCH(J13, Thang_BF!$C$2:$C$223, 0)) -> 07 | J13: 56 | K13: =(G13-G14)*111/3 -> 7.4 | L13: tây tây bắc | M13: 1002
A14: quá khứ | B14: =TEXT(D14,"00")&"/"&TEXT(E14,"00")&" - "&C14&"h" -> 05/11 - 13h | C14: 13 | D14: 5 | E14: 11 | F14: 8 | G14: 142.7 | H14: =INDEX(Thang_BF!$A$2:$A$223, MATCH(I14, Thang_BF!$B$2:$B$223, 0)) -> TD | I14: =INDEX(Thang_BF!$B$2:$B$223, MATCH(J14, Thang_BF!$C$2:$C$223, 0)) -> 07 | J14: 56 | K14: =(G14-G15)*111/3 -> 0 | L14: tây tây bắc | M14: 1000
A15: quá khứ | B15: =TEXT(D15,"00")&"/"&TEXT(E15,"00")&" - "&C15&"h" -> 05/11 - 16h | C15: 16 | D15: 5 | E15: 11 | F15: 8.3 | G15: 142.7 | H15: =INDEX(Thang_BF!$A$2:$A$223, MATCH(I15, Thang_BF!$B$2:$B$223, 0)) -> TD | I15: =INDEX(Thang_BF!$B$2:$B$223, MATCH(J15, Thang_BF!$C$2:$C$223, 0)) -> 07 | J15: 56 | K15: =(G15-G16)*111/3 -> 0 | L15: tây tây bắc | M15: 1000
A16: quá khứ | B16: =TEXT(D16,"00")&"/"&TEXT(E16,"00")&" - "&C16&"h" -> 05/11 - 19h | C16: 19 | D16: 5 | E16: 11 | F16: 9.2 | G16: 142.7 | H16: =INDEX(Thang_BF!$A$2:$A$223, MATCH(I16, Thang_BF!$B$2:$B$223, 0)) -> TD | I16: =INDEX(Thang_BF!$B$2:$B$223, MATCH(J16, Thang_BF!$C$2:$C$223, 0)) -> 07 | J16: 56 | K16: =(G16-G17)*111/3 -> 3.7 | L16: tây tây bắc | M16: 1000
A17: quá khứ | B17: =TEXT(D17,"00")&"/"&TEXT(E17,"00")&" - "&C17&"h" -> 05/11 - 22h | C17: 22 | D17: 5 | E17: 11 | F17: 9.1 | G17: 142.6 | H17: =INDEX(Thang_BF!$A$2:$A$223, MATCH(I17, Thang_BF!$B$2:$B$223, 0)) -> TD | I17: =INDEX(Thang_BF!$B$2:$B$223, MATCH(J17, Thang_BF!$C$2:$C$223, 0)) -> 07 | J17: 56 | K17: =(G17-G18)*111/3 -> 18.5 | L17: tây tây bắc | M17: 1000
A18: quá khứ | B18: =TEXT(D18,"00")&"/"&TEXT(E18,"00")&" - "&C18&"h" -> 06/11 - 01h | C18: 01 | D18: 6 | E18: 11 | F18: 10.2 | G18: 142.1 | H18: =INDEX(Thang_BF!$A$2:$A$223, MATCH(I18, Thang_BF!$B$2:$B$223, 0)) -> TS | I18: =INDEX(Thang_BF!$B$2:$B$223, MATCH(J18, Thang_BF!$C$2:$C$223, 0)) -> 08 | J18: 65 | K18: =(G18-G19)*111/3 -> 14.8 | L18: tây tây bắc | M18: 998
A19: quá khứ | B19: =TEXT(D19,"00")&"/"&TEXT(E19,"00")&" - "&C19&"h" -> 06/11 - 04h | C19: 04 | D19: 6 | E19: 11 | F19: 10.3 | G19: 141.7 | H19: =INDEX(Thang_BF!$A$2:$A$223, MATCH(I19, Thang_BF!$B$2:$B$223, 0)) -> TS | I19: =INDEX(Thang_BF!$B$2:$B$223, MATCH(J19, Thang_BF!$C$2:$C$223, 0)) -> 08 | J19: 65 | K19: =(G19-G20)*111/3 -> 18.5 | L19: tây tây bắc | M19: 998
A20: quá khứ | B20: =TEXT(D20,"00")&"/"&TEXT(E20,"00")&" - "&C20&"h" -> 06/11 - 07h | C20: 07 | D20: 6 | E20: 11 | F20: 10.4 | G20: 141.2 | H20: =INDEX(Thang_BF!$A$2:$A$223, MATCH(I20, Thang_BF!$B$2:$B$223, 0)) -> TS | I20: =INDEX(Thang_BF!$B$2:$B$223, MATCH(J20, Thang_BF!$C$2:$C$223, 0)) -> 08 | J20: 74 | K20: =(G20-G21)*111/3 -> 29.6 | L20: tây tây bắc | M20: 994
A21: quá khứ | B21: =TEXT(D21,"00")&"/"&TEXT(E21,"00")&" - "&C21&"h" -> 06/11 - 10h | C21: 10 | D21: 6 | E21: 11 | F21: 10.2 | G21: 140.4 | H21: =INDEX(Thang_BF!$A$2:$A$223, MATCH(I21, Thang_BF!$B$2:$B$223, 0)) -> TS | I21: =INDEX(Thang_BF!$B$2:$B$223, MATCH(J21, Thang_BF!$C$2:$C$223, 0)) -> 08 | J21: 74 | K21: =(G21-G22)*111/3 -> 22.2 | L21: tây tây bắc | M21: 994
A22: quá khứ | B22: =TEXT(D22,"00")&"/"&TEXT(E22,"00")&" - "&C22&"h" -> 06/11 - 13h | C22: 13 | D22: 6 | E22: 11 | F22: 10.2 | G22: 139.8 | H22: =INDEX(Thang_BF!$A$2:$A$223, MATCH(I22, Thang_BF!$B$2:$B$223, 0)) -> TS | I22: =INDEX(Thang_BF!$B$2:$B$223, MATCH(J22, Thang_BF!$C$2:$C$223, 0)) -> 08 | J22: 74 | K22: =(G22-G23)*111/3 -> 7.4 | L22: tây tây bắc | M22: 994
A23: quá khứ | B23: =TEXT(D23,"00")&"/"&TEXT(E23,"00")&" - "&C23&"h" -> 06/11 - 16h | C23: 16 | D23: 6 | E23: 11 | F23: 10.1 | G23: 139.6 | H23: =INDEX(Thang_BF!$A$2:$A$223, MATCH(I23, Thang_BF!$B$2:$B$223, 0)) -> TS | I23: =INDEX(Thang_BF!$B$2:$B$223, MATCH(J23, Thang_BF!$C$2:$C$223, 0)) -> 08 | J23: 74 | K23: =(G23-G24)*111/3 -> 7.4 | L23: tây tây bắc | M23: 994
A24: quá khứ | B24: =TEXT(D24,"00")&"/"&TEXT(E24,"00")&" - "&C24&"h" -> 06/11 - 19h | C24: 19 | D24: 6 | E24: 11 | F24: 10.5 | G24: 139.4 | H24: =INDEX(Thang_BF!$A$2:$A$223, MATCH(I24, Thang_BF!$B$2:$B$223, 0)) -> STS | I24: =INDEX(Thang_BF!$B$2:$B$223, MATCH(J24, Thang_BF!$C$2:$C$223, 0)) -> 10 | J24: 93 | K24: =(G24-G25)*111/3 -> 14.8 | L24: tây tây bắc | M24: 985
A25: quá khứ | B25: =TEXT(D25,"00")&"/"&TEXT(E25,"00")&" - "&C25&"h" -> 06/11 - 22h | C25: 22 | D25: 6 | E25: 11 | F25: 10.7 | G25: 139 | H25: =INDEX(Thang_BF!$A$2:$A$223, MATCH(I25, Thang_BF!$B$2:$B$223, 0)) -> STS | I25: =INDEX(Thang_BF!$B$2:$B$223, MATCH(J25, Thang_BF!$C$2:$C$223, 0)) -> 10 | J25: 93 | K25: =(G25-G26)*111/3 -> 3.7 | L25: tây tây bắc | M25: 985
A26: quá khứ | B26: =TEXT(D26,"00")&"/"&TEXT(E26,"00")&" - "&C26&"h" -> 07/11 - 01h | C26: 01 | D26: 7 | E26: 11 | F26: 11 | G26: 138.9 | H26: =INDEX(Thang_BF!$A$2:$A$223, MATCH(I26, Thang_BF!$B$2:$B$223, 0)) -> STS | I26: =INDEX(Thang_BF!$B$2:$B$223, MATCH(J26, Thang_BF!$C$2:$C$223, 0)) -> 10 | J26: 102 | K26: =(G26-G27)*111/3 -> 7.4 | L26: tây tây bắc | M26: 980
A27: quá khứ | B27: =TEXT(D27,"00")&"/"&TEXT(E27,"00")&" - "&C27&"h" -> 07/11 - 04h | C27: 04 | D27: 7 | E27: 11 | F27: 11.3 | G27: 138.7 | H27: =INDEX(Thang_BF!$A$2:$A$223, MATCH(I27, Thang_BF!$B$2:$B$223, 0)) -> STS | I27: =INDEX(Thang_BF!$B$2:$B$223, MATCH(J27, Thang_BF!$C$2:$C$223, 0)) -> 11 | J27: 111 | K27: =(G27-G28)*111/3 -> 18.5 | L27: tây tây bắc | M27: 975
A28: quá khứ | B28: =TEXT(D28,"00")&"/"&TEXT(E28,"00")&" - "&C28&"h" -> 07/11 - 07h | C28: 07 | D28: 7 | E28: 11 | F28: 11.5 | G28: 138.2 | H28: =INDEX(Thang_BF!$A$2:$A$223, MATCH(I28, Thang_BF!$B$2:$B$223, 0)) -> STS | I28: =INDEX(Thang_BF!$B$2:$B$223, MATCH(J28, Thang_BF!$C$2:$C$223, 0)) -> 11 | J28: 111 | K28: =(G28-G29)*111/3 -> 25.9 | L28: tây tây bắc | M28: 975
A29: quá khứ | B29: =TEXT(D29,"00")&"/"&TEXT(E29,"00")&" - "&C29&"h" -> 07/11 - 10h | C29: 10 | D29: 7 | E29: 11 | F29: 11.7 | G29: 137.5 | H29: =INDEX(Thang_BF!$A$2:$A$223, MATCH(I29, Thang_BF!$B$2:$B$223, 0)) -> STS | I29: =INDEX(Thang_BF!$B$2:$B$223, MATCH(J29, Thang_BF!$C$2:$C$223, 0)) -> 11 | J29: 111 | K29: =(G29-G30)*111/3 -> 33.3 | L29: tây tây bắc | M29: 975
A30: quá khứ | B30: =TEXT(D30,"00")&"/"&TEXT(E30,"00")&" - "&C30&"h" -> 07/11 - 13h | C30: 13 | D30: 7 | E30: 11 | F30: 11.7 | G30: 136.6 | H30: =INDEX(Thang_BF!$A$2:$A$223, MATCH(I30, Thang_BF!$B$2:$B$223, 0)) -> STS | I30: =INDEX(Thang_BF!$B$2:$B$223, MATCH(J30, Thang_BF!$C$2:$C$223, 0)) -> 11 | J30: 111 | K30: =(G30-G31)*111/3 -> 18.5 | L30: tây tây bắc | M30: 975
A31: quá khứ | B31: =TEXT(D31,"00")&"/"&TEXT(E31,"00")&" - "&C31&"h" -> 07/11 - 16h | C31: 16 | D31: 7 | E31: 11 | F31: 11.9 | G31: 136.1 | H31: =INDEX(Thang_BF!$A$2:$A$223, MATCH(I31, Thang_BF!$B$2:$B$223, 0)) -> STS | I31: =INDEX(Thang_BF!$B$2:$B$223, MATCH(J31, Thang_BF!$C$2:$C$223, 0)) -> 11 | J31: 111 | K31: =(G31-G32)*111/3 -> 22.2 | L31: tây tây bắc | M31: 975
A32: quá khứ | B32: =TEXT(D32,"00")&"/"&TEXT(E32,"00")&" - "&C32&"h" -> 07/11 - 19h | C32: 19 | D32: 7 | E32: 11 | F32: 12 | G32: 135.5 | H32: =INDEX(Thang_BF!$A$2:$A$223, MATCH(I32, Thang_BF!$B$2:$B$223, 0)) -> STS | I32: =INDEX(Thang_BF!$B$2:$B$223, MATCH(J32, Thang_BF!$C$2:$C$223, 0)) -> 11 | J32: 111 | K32: =(G32-G33)*111/3 -> 25.9 | L32: tây tây bắc | M32: 975
A33: quá khứ | B33: =TEXT(D33,"00")&"/"&TEXT(E33,"00")&" - "&C33&"h" -> 07/11 - 22h | C33: 22 | D33: 7 | E33: 11 | F33: 12 | G33: 134.8 | H33: =INDEX(Thang_BF!$A$2:$A$223, MATCH(I33, Thang_BF!$B$2:$B$223, 0)) -> STS | I33: =INDEX(Thang_BF!$B$2:$B$223, MATCH(J33, Thang_BF!$C$2:$C$223, 0)) -> 11 | J33: 111 | K33: =(G33-G34)*111/3 -> 22.2 | L33: tây tây bắc | M33: 975
A34: quá khứ | B34: =TEXT(D34,"00")&"/"&TEXT(E34,"00")&" - "&C34&"h" -> 08/11 - 01h | C34: 01 | D34: 8 | E34: 11 | F34: 12.2 | G34: 134.2 | H34: =INDEX(Thang_BF!$A$2:$A$223, MATCH(I34, Thang_BF!$B$2:$B$223, 0)) -> TY | I34: =INDEX(Thang_BF!$B$2:$B$223, MATCH(J34, Thang_BF!$C$2:$C$223, 0)) -> 12 | J34: 120 | K34: =(G34-G35)*111/3 -> 29.6 | L34: tây tây bắc | M34: 970
A35: quá khứ | B35: =TEXT(D35,"00")&"/"&TEXT(E35,"00")&" - "&C35&"h" -> 08/11 - 04h | C35: 04 | D35: 8 | E35: 11 | F35: 12.4 | G35: 133.4 | H35: =INDEX(Thang_BF!$A$2:$A$223, MATCH(I35, Thang_BF!$B$2:$B$223, 0)) -> TY | I35: =INDEX(Thang_BF!$B$2:$B$223, MATCH(J35, Thang_BF!$C$2:$C$223, 0)) -> 12 | J35: 130 | K35: =(G35-G36)*111/3 -> 40.7 | L35: tây tây bắc | M35: 965
A36: quá khứ | B36: =TEXT(D36,"00")&"/"&TEXT(E36,"00")&" - "&C36&"h" -> 08/11 - 07h | C36: 07 | D36: 8 | E36: 11 | F36: 12.8 | G36: 132.3 | H36: =INDEX(Thang_BF!$A$2:$A$223, MATCH(I36, Thang_BF!$B$2:$B$223, 0)) -> TY | I36: =INDEX(Thang_BF!$B$2:$B$223, MATCH(J36, Thang_BF!$C$2:$C$223, 0)) -> 13 | J36: =40*3.6 -> 144 | K36: =(G36-G37)*111/3 -> 37 | L36: tây tây bắc | M36: 960
A37: quá khứ | B37: =TEXT(D37,"00")&"/"&TEXT(E37,"00")&" - "&C37&"h" -> 08/11 - 10h | C37: 10 | D37: 8 | E37: 11 | F37: 12.7 | G37: 131.3 | H37: =INDEX(Thang_BF!$A$2:$A$223, MATCH(I37, Thang_BF!$B$2:$B$223, 0)) -> TY | I37: =INDEX(Thang_BF!$B$2:$B$223, MATCH(J37, Thang_BF!$C$2:$C$223, 0)) -> 14 | J37: 151 | K37: =(G37-G38)*111/3 -> 22.2 | L37: tây tây bắc | M37: 955
A38: quá khứ | B38: =TEXT(D38,"00")&"/"&TEXT(E38,"00")&" - "&C38&"h" -> 08/11 - 13h | C38: 13 | D38: 8 | E38: 11 | F38: 13 | G38: 130.7 | H38: =INDEX(Thang_BF!$A$2:$A$223, MATCH(I38, Thang_BF!$B$2:$B$223, 0)) -> TY | I38: =INDEX(Thang_BF!$B$2:$B$223, MATCH(J38, Thang_BF!$C$2:$C$223, 0)) -> 14 | J38: 151 | K38: =(G38-G39)*111/3 -> 40.7 | L38: tây tây bắc | M38: 955
A39: quá khứ | B39: =TEXT(D39,"00")&"/"&TEXT(E39,"00")&" - "&C39&"h" -> 08/11 - 16h | C39: 16 | D39: 8 | E39: 11 | F39: 13.1 | G39: 129.6 | H39: =INDEX(Thang_BF!$A$2:$A$223, MATCH(I39, Thang_BF!$B$2:$B$223, 0)) -> TY | I39: =INDEX(Thang_BF!$B$2:$B$223, MATCH(J39, Thang_BF!$C$2:$C$223, 0)) -> 14 | J39: 151 | K39: =(G39-G40)*111/3 -> 44.4 | L39: tây tây bắc | M39: 955
A40: quá khứ | B40: =TEXT(D40,"00")&"/"&TEXT(E40,"00")&" - "&C40&"h" -> 08/11 - 19h | C40: 19 | D40: 8 | E40: 11 | F40: 13.2 | G40: 128.4 | H40: =INDEX(Thang_BF!$A$2:$A$223, MATCH(I40, Thang_BF!$B$2:$B$223, 0)) -> TY | I40: =INDEX(Thang_BF!$B$2:$B$223, MATCH(J40, Thang_BF!$C$2:$C$223, 0)) -> 14 | J40: 151 | K40: =(G40-G41)*111/3 -> 33.3 | L40: tây tây bắc | M40: 955
...

Sheet Thang_BF
A1: thang BF | B1: cấp | C1: Vmax
B2: 00 | C2: 0
B3: 01 | C3: 1
B4: 01 | C4: 2
B5: 01 | C5: 3
B6: 01 | C6: 4
B7: 01 | C7: 5
B8: 02 | C8: 6
B9: 02 | C9: 7
B10: 02 | C10: 8
B11: 02 | C11: 9
B12: 02 | C12: 10
B13: 02 | C13: 11
... B21: 03 | C21: 19
A22: vungthap | B22: 04 | C22: 20
A23: vungthap | B23: 04 | C23: 21
A24: vungthap | B24: 04 | C24: 22
A25: vungthap | B25: 04 | C25: 23
A26: vungthap | B26: 04 | C26: 24
A27: vungthap | B27: 04 | C27: 25
A28: vungthap | B28: 04 | C28: 26
A29: vungthap | B29: 04 | C29: 27
A30: vungthap | B30: 04 | C30: 28
A31: vungthap | B31: 05 | C31: 29
A32: vungthap | B32: 05 | C32: 30
A33: vungthap | B33: 05 | C33: 31
... A90: TS | B90: 09 | C90: 88
A91: STS | B91: 10 | C91: 89
A92: STS | B92: 10 | C92: 90
A93: STS | B93: 10 | C93: 91
A94: STS | B94: 10 | C94: 92
A95: STS | B95: 10 | C95: 93
A96: STS | B96: 10 | C96: 94
A97: STS | B97: 10 | C97: 95
A98: STS | B98: 10 | C98: 96
A99: STS | B99: 10 | C99: 97
A100: STS | B100: 10 | C100: 98
A101: STS | B101: 10 | C101: 99
A102: STS | B102: 10 | C102: 100
... A223: STY | B223: 17 | C223: 221
